Workbook

Sheet JOB ORDER
I1: 1042 Vinzons Ave. P1 Brgy. Gahonon Daet, Camarines Norte
I2: Telephone No. 09187747788 / 09757210388
I3: Email Add: trufitautocenter@gmail.com
A6: JOB ORDER
A7: Page 1 of 1 | K7: ='JOB ESTIMATE'!K7:L7 -> JO NO. | M7: ='JOB ESTIMATE'!M7 -> 0
A8: Plate No.: | C8: Customer Name & Address | G8: Home Phone No. | H8: Color | K8: Warranty Exp. Kms | M8: Payment Method
A9: ='JOB ESTIMATE'!A8:B9 -> 0 | C9: ='JOB ESTIMATE'!C8:F10 -> 0 | H9: ='JOB ESTIMATE'!H9:J9 -> white | M9: Cash
G10: Business Phone No: | H10: Year / Make / Model | K10: Selling Dealer
A11: ='JOB ESTIMATE'!A11:B11 -> Customer No.: | H11: ='JOB ESTIMATE'!H10:J12 -> 0 | M11: Credit Card
A12: ='JOB ESTIMATE'!A12:B12 | C12: ='JOB ESTIMATE'!C11:F13 -> 0 | G12: Mobile No. | K12: Warr. Exp. Date
A13: Date/Time Received | G13: ='JOB ESTIMATE'!G13 -> 0 | M13: Cheque
A14: ='JOB ESTIMATE'!A14:B14 -> 0 | G14: ='JOB ESTIMATE'!G14 -> 0 | H14: VIN / Serial No. | K14: Stock No.
A15: Released Date: | C15: Department / Team | E15: Maint. Code | G15: TIN | H15: ='JOB ESTIMATE'!H14:J15 -> 0 | M15: Charge Acct.
A16: ='JOB ESTIMATE'!A16:B16 -> 0
A17: Service Advisor No. | C17: Service Advisor Name | F17: ='JOB ESTIMATE'!F17:G17 -> Date Finished: | H17: Kilometers | K17: Engine No.
C18: ='JOB ESTIMATE'!C18:E18 -> 0 | F18: ='JOB ESTIMATE'!F18:G18 -> 0 | H18: ='JOB ESTIMATE'!H18:J18 -> 0 | K18: ='JOB ESTIMATE'!K18:L18 -> 0
A20: Labour | C20: Operation | F20: Description
E21: ='JOB ESTIMATE'!E20 -> 0
E22: ='JOB ESTIMATE'!E21 -> 0
E23: ='JOB ESTIMATE'!E22 -> 0
E24: ='JOB ESTIMATE'!E23 -> 0
E25: ='JOB ESTIMATE'!E24 -> 0
E26: ='JOB ESTIMATE'!E25 -> 0
E27: ='JOB ESTIMATE'!E26 -> 0
E28: ='JOB ESTIMATE'!E27 -> 0
E29: ='JOB ESTIMATE'!E28 -> 0
E30: ='JOB ESTIMATE'!E29 -> 0
E31: ='JOB ESTIMATE'!E30 -> 0
A41: RECOMMENDATION
A63: I hereby authorize Trufit Auto Center to proceed with the repair work to be done along with the necessary materials/parts. Trufit Auto Center will not be held responsible for any loss or damage to vehicle in case of fire, theft, accident, or any other cause beyond their control, nor shall Trufit Auto Center be held responsible for delays caused by unavailability of parts or delays in parts shipments by the supplier or the transporter. My signature hereto is evidence of my full understanding and acknowledgment of the conditions covered herein.
C66: CUSTOMER'S SIGNATURE / DATE / TIME

Sheet BILLING
I1: 1042 Vinzons Ave. P1 Brgy. Gahonon Daet, Camarines Norte
I2: Telephone No. 09187747788 / 09757210388
I3: Email Add: trufitautocenter@gmail.com
A6: BILLING STATEMENT
A7: Page 1 of 1 | K7: JO NO.
A8: Plate No.: | C8: Customer Name & Address | G8: Home Phone No. | H8: Color | K8: Warranty Exp. Kms | M8: Payment Method
A9: ='JOB ESTIMATE'!A9:B10 -> 0 | C9: ='JOB ESTIMATE'!C9:F11 -> 0 | H9: ='JOB ESTIMATE'!H9:J9 -> white | M9: Cash
G10: Business Phone No: | H10: Year / Make / Model | K10: Selling Dealer
A11: Customer No.: | H11: ='JOB ESTIMATE'!H11:J13 -> 0 | M11: Credit Card
C12: ='JOB ESTIMATE'!C12:F14 -> 0 | G12: Mobile No. | K12: Warr. Exp. Date
A13: Date/Time Received | G13: ='JOB ESTIMATE'!G13 -> 0 | M13: Cheque
A14: ='JOB ESTIMATE'!A14:B14 -> 0 | G14: ='JOB ESTIMATE'!G14 -> 0 | H14: VIN / Serial No. | K14: Stock No.
A15: Date Released: | C15: Department / Team | E15: Maint. Code | G15: TIN | H15: ='JOB ESTIMATE'!H15:J16 -> 0 | M15: Charge Acct.
A17: Service Advisor No. | C17: Service Advisor Name | F17: Date Finished: | H17: Kilometers | K17: Engine No.
C18: ='JOB ESTIMATE'!C18:E18 -> 0 | H18: ='JOB ESTIMATE'!H18:J18 -> 0 | K18: ='JOB ESTIMATE'!K18:L18 -> 0
A19: Labour | C19: Operation | F19: Description | K19: Units | M19: Amount
E20: ='JOB ESTIMATE'!E20:G20 -> 0 | K20: ='JOB ESTIMATE'!K20 -> 0 | M20: =K20 -> 0 | N20: =SUM(M20:M26) -> 0 | O20: TOTAL LABOR
E21: ='JOB ESTIMATE'!E21 -> 0 | K21: ='JOB ESTIMATE'!K21 -> 0 | M21: =K21 -> 0 | N21: =SUM(M32:M38) -> 0 | O21: TOTAL PARTS
E22: ='JOB ESTIMATE'!E22 -> 0 | K22: ='JOB ESTIMATE'!K22 -> 0 | M22: =K22 -> 0 | N22: =SUM(M40:M47) -> 0 | O22: TOTAL SPOL
E23: ='JOB ESTIMATE'!E23 -> 0 | K23: ='JOB ESTIMATE'!K23 -> 0 | M23: =K23 -> 0 | N23: =SUM(N20:N22) -> 0 | O23: TOTAL SALES
E24: ='JOB ESTIMATE'!E24 -> 0 | K24: ='JOB ESTIMATE'!K24 -> 0 | M24: =K24 -> 0
E25: ='JOB ESTIMATE'!E25 -> 0 | K25: ='JOB ESTIMATE'!K25 -> 0 | M25: =K25 -> 0
E26: ='JOB ESTIMATE'!E26 -> 0 | K26: ='JOB ESTIMATE'!K26 -> 0 | M26: =K26 -> 0
E27: ='JOB ESTIMATE'!E27 -> 0 | K27: ='JOB ESTIMATE'!K27 -> 0 | M27: =K27 -> 0
E28: ='JOB ESTIMATE'!E28 -> 0 | K28: ='JOB ESTIMATE'!K28 -> 0 | M28: =K28 -> 0
A31: Parts Number | E31: Description | I31: Qty | K31: Unit Price | M31: Amount
A32: ='JOB ESTIMATE'!A34:B34 -> 0 | D32: ='JOB ESTIMATE'!D34 -> 0 | I32: ='JOB ESTIMATE'!I34 -> 0 | K32: ='JOB ESTIMATE'!K34 -> 0 | M32: =K32*I32 -> 0
A33: ='JOB ESTIMATE'!A35:B35 -> 0 | D33: ='JOB ESTIMATE'!D35 -> 0 | I33: ='JOB ESTIMATE'!I35 -> 0 | K33: ='JOB ESTIMATE'!K35 -> 0 | M33: =K33*I33 -> 0
A34: ='JOB ESTIMATE'!A36:B36 -> 0 | D34: ='JOB ESTIMATE'!D36 -> 0 | I34: ='JOB ESTIMATE'!I36 -> 0 | K34: ='JOB ESTIMATE'!K36 -> 0 | M34: =K34*I34 -> 0
A35: ='JOB ESTIMATE'!A39:B39 -> 0 | D35: ='JOB ESTIMATE'!D39 -> 0 | I35: ='JOB ESTIMATE'!I37 -> 0 | K35: ='JOB ESTIMATE'!K39 -> 0 | M35: =K35*I35 -> 0
A36: ='JOB ESTIMATE'!A40:B40 -> 0 | D36: ='JOB ESTIMATE'!D40 -> 0 | I36: ='JOB ESTIMATE'!I38 -> 0 | K36: ='JOB ESTIMATE'!K40 -> 0 | M36: =K36*I36 -> 0
M37: =K37*I37 -> 0
M38: =K38*I38 -> 0
A39: Supplies, Petrol, Oils, and Lubricants | M39: Amount
E40: ='JOB ESTIMATE'!E43 -> Sundries | I40: ='JOB ESTIMATE'!I43 -> 0 | K40: ='JOB ESTIMATE'!K43 -> 0 | M40: =K40 -> 0
E41: 0 | I41: 0 | K41: ='JOB ESTIMATE'!K44 -> 0 | M41: =K41 -> 0
E42: ='JOB ESTIMATE'!E45 -> 0 | I42: ='JOB ESTIMATE'!I45 -> 0 | K42: ='JOB ESTIMATE'!K45 -> 0 | M42: =K42 -> 0
E43: ='JOB ESTIMATE'!E46 -> 0 | I43: ='JOB ESTIMATE'!I46 -> 0 | K43: ='JOB ESTIMATE'!K46 -> 0 | M43: =K43 -> 0
E44: ='JOB ESTIMATE'!E47 -> 0 | I44: ='JOB ESTIMATE'!I47 -> 0 | K44: ='JOB ESTIMATE'!K47 -> 0 | M44: =K44 -> 0
E45: ='JOB ESTIMATE'!E48 -> 0 | I45: ='JOB ESTIMATE'!I48 -> 0 | K45: ='JOB ESTIMATE'!K48 -> 0 | M45: =K45 -> 0
...

Sheet JOB ESTIMATE
I1: 1042 Vinzons Ave. P1 Brgy. Gahonon Daet, Camarines Norte
I2: Telephone No. 09187747788 / 09757210388
I3: Email Add: trufitautocenter@gmail.com
A6: JOB ESTIMATE
A7: Page 1 of 1 | K7: JO NO.
A8: Plate No.: | C8: Customer Name & Address | G8: Home Phone No. | H8: Color | K8: Warranty Exp. Kms | M8: Payment Method
H9: white | M9: Cash
G10: Business Phone No: | H10: Year / Make / Model | K10: Selling Dealer
A11: Customer No.: | M11: Credit Card
G12: Mobile No. | K12: Warr. Exp. Date | N12: =SUM(M21:M26) -> 0 | O12: TOTAL LABOR
A13: Date/Time Received | M13: Cheque | N13: =SUM(M34:M40) -> 0 | O13: TOTAL PARTS
H14: VIN / Serial No. | K14: Stock No. | N14: =SUM(M44:M50) -> 0 | O14: TOTAL SPOL
A15: Date Released: | C15: Department / Team | E15: Maint. Code | G15: TIN | M15: Charge Acct. | N15: =SUM(N12:N14) -> 0 | O15: TOTAL SALES
A17: Service Advisor No. | C17: Service Advisor Name | F17: Date Finished: | H17: Kilometers | K17: Engine No.
A19: Labour | F19: Description | K19: Units | M19: Amount
M23: =K23 -> 0
M24: =K24 -> 0
M25: =K25 -> 0
M26: =K26 -> 0
M27: =K27 -> 0
M28: =K28 -> 0
M29: =K29 -> 0
M30: =K30 -> 0
A33: Parts Number | E33: Description | I33: Qty | K33: Unit Price | M33: Amount
M34: =K34*I34 -> 0
M35: =K35*I35 -> 0
M36: =K36*I36 -> 0
M37: =K37*I37 -> 0
M38: =K38*I38 -> 0
M39: =K39*I39 -> 0
M40: =I40*K40 -> 0
A42: Supplies, Petrol, Oils, and Lubricants
E43: Sundries
M44: =I44*K44 -> 0
M45: =I45*K45 -> 0
M46: =I46*K46 -> 0
M47: =I47*K47 -> 0
M48: =I48*K48 -> 0
M49: =I49*K49 -> 0
A50: Comments | M50: =K50*I50 -> 0
...

Sheet SCANNED DOCS

Sheet JOB REQUEST TECH
A4: TECH | B4: JOB DONE | C4: P | E4: A
B5: ='JOB ESTIMATE'!E20 -> 0
A31: RECOMMENDATION | C31: ROADTEST LOG
D32: MILAGE | E32: FUEL
E33: E | F
E35: E | F
E37: E | F
E39: E | F
E41: E | F

Sheet PMRIS
A1: Name: | B1: ='JOB ESTIMATE'!C9 -> 0 | D1: Date Required | E1: ='JOB ESTIMATE'!A12 | H1: Name: | I1: =B1 -> 0 | K1: Date Required | L1: =E1
A3: Make / Model | D3: Plate No.: | H3: Make / Model | K3: Plate No.:
A4: ='JOB ESTIMATE'!H11 -> 0 | E4: ='JOB ESTIMATE'!A9 -> 0 | H4: =A4 -> 0 | L4: =E4 -> 0
A5: Chasis Number | D5: Engine Number: | H5: Chasis Number | K5: Engine Number:
A6: ='JOB ESTIMATE'!H15 -> 0 | E6: ='JOB ESTIMATE'!K18 -> 0 | H6: =A6 -> 0 | L6: =E6 -> 0
C7: PARTS REQUISITION | J7: PARTS REQUISITION
A10: Qty. | B10: Part No. | C10: Description | E10: Remarks | H10: Qty. | I10: Part No. | J10: Description | L10: Remarks
A11: ='JOB ESTIMATE'!I34 -> 0 | B11: ='JOB ESTIMATE'!A34 -> 0 | C11: ='JOB ESTIMATE'!E34 -> 0 | H11: =A11 -> 0 | I11: =B11 -> 0 | J11: =C11 -> 0
A12: ='JOB ESTIMATE'!I35 -> 0 | B12: ='JOB ESTIMATE'!A35 -> 0 | C12: ='JOB ESTIMATE'!E35 -> 0 | H12: =A12 -> 0 | I12: =B12 -> 0 | J12: =C12 -> 0
A13: ='JOB ESTIMATE'!I36 -> 0 | B13: ='JOB ESTIMATE'!A36 -> 0 | C13: ='JOB ESTIMATE'!E36 -> 0 | H13: =A13 -> 0 | I13: =B13 -> 0 | J13: =C13 -> 0
A14: ='JOB ESTIMATE'!I37 -> 0 | B14: ='JOB ESTIMATE'!A37 -> 0 | C14: ='JOB ESTIMATE'!E37 -> 0 | H14: =A14 -> 0 | I14: =B14 -> 0 | J14: =C14 -> 0
A15: ='JOB ESTIMATE'!I38 -> 0 | B15: ='JOB ESTIMATE'!A38 -> 0 | C15: ='JOB ESTIMATE'!E38 -> 0 | H15: =A15 -> 0 | I15: =B15 -> 0 | J15: =C15 -> 0
A16: ='JOB ESTIMATE'!I39 -> 0 | B16: ='JOB ESTIMATE'!A39 -> 0 | C16: ='JOB ESTIMATE'!E39 -> 0 | H16: =A16 -> 0 | I16: =B16 -> 0 | J16: =C16 -> 0
A17: ='JOB ESTIMATE'!I40 -> 0 | B17: ='JOB ESTIMATE'!A40 -> 0 | C17: ='JOB ESTIMATE'!E40 -> 0 | H17: =A17 -> 0 | I17: =B17 -> 0 | J17: =C17 -> 0
C19: ='JOB ESTIMATE'!E43 -> Sundries | J19: =C19 -> Sundries
A20: ='JOB ESTIMATE'!I44 -> 0 | C20: ='JOB ESTIMATE'!E44 -> 0 | H20: =A20 -> 0 | J20: =C20 -> 0
A21: ='JOB ESTIMATE'!I45 -> 0 | C21: ='JOB ESTIMATE'!E45 -> 0 | H21: =A21 -> 0 | J21: =C21 -> 0
A22: ='JOB ESTIMATE'!I46 -> 0 | C22: ='JOB ESTIMATE'!E46 -> 0 | H22: =A22 -> 0 | J22: =C22 -> 0
A23: ='JOB ESTIMATE'!I47 -> 0 | C23: ='JOB ESTIMATE'!E47 -> 0 | H23: =A23 -> 0 | J23: =C23 -> 0
A24: ='JOB ESTIMATE'!I48 -> 0 | C24: ='JOB ESTIMATE'!E48 -> 0 | H24: =A24 -> 0 | J24: =C24 -> 0
A25: ='JOB ESTIMATE'!I49 -> 0 | C25: ='JOB ESTIMATE'!E49 -> 0 | H25: =A25 -> 0 | J25: =C25 -> 0
A26: ='JOB ESTIMATE'!I50 -> 0 | C26: ='JOB ESTIMATE'!E50 -> 0 | H26: =A26 -> 0 | J26: =C26 -> 0
A31: Requested By | D31: Received By: | H31: Requested By | K31: Received By:
A33: Noted by: | D33: Approved By: | H33: Noted by: | K33: Approved By:
A35: Service Advisor Copy | H35: Purchasing Copy

Sheet UPDATE SHEET
A1: UPDATE SHEET
A2: Date: | B2: Time: | C2: Details: | G2: By:

Sheet SCANNED DOCS (2)

Sheet PRICE
A1: AIR FILTER
A2: FAS-8951 | B2: 360 | C2: =B2-(B2*0.25) -> 270
A3: FAS-8500 | B3: 1250 | C3: =B3-(B3*0.25) -> 937.5 | G3: Air Filter
A4: FAS-8345 | B4: 493 | C4: =B4-(B4*0.25) -> 369.75 | G4: Cabin Filter
A5: FAS-8977 | B5: 750 | C5: =B5-(B5*0.25) -> 562.5 | G5: Oil Filter
A6: FAS-8640 | B6: 1900 | C6: =B6-(B6*0.25) -> 1425 | G6: Fuel Filter
A7: FAS 8024 | B7: 880 | C7: =B7-(B7*0.25) -> 660 | G7: Brake pads
A8: FAS-8342 | B8: 650 | C8: =B8-(B8*0.25) -> 487.5 | G8: Brake Shoe
A9: FAS-8344 | B9: 750 | C9: =B9-(B9*0.25) -> 562.5 | G9: Rotor Disc
A10: FAS-8553 | B10: 420 | C10: =B10-(B10*0.25) -> 315
A11: FAS-8555 | B11: 515 | C11: =B11-(B11*0.25) -> 386.25
A12: FAS-8712 | B12: 1200 | C12: =B12-(B12*0.25) -> 900
A13: FAS-8856 | B13: 428 | C13: =B13-(B13*0.25) -> 321
A14: FAS-8865 | B14: 650 | C14: =B14-(B14*0.25) -> 487.5
A15: FAS-8866 | B15: 680 | C15: =B15-(B15*0.25) -> 510
A16: FAS-8867 | B16: 700 | C16: =B16-(B16*0.25) -> 525
A17: FAS-8588 | B17: 320 | C17: =B17-(B17*0.25) -> 240
A18: FAS-8861 | B18: 950 | C18: =B18-(B18*0.25) -> 712.5
A19: FAS-8862 | B19: 750 | C19: =B19-(B19*0.25) -> 562.5
A20: FAS-8348 | B20: 500 | C20: =B20-(B20*0.25) -> 375
A21: FAS-8641 | B21: 1028 | C21: =B21-(B21*0.25) -> 771
... A55: FAS 8529 | B55: 815 | C55: =B55-(B55*0.25) -> 611.25
A57: CABIN FILTER
A58: FCS-9530 | B58: 665 | C58: =B58-(B58*0.25) -> 498.75
A59: FCS-9640 | B59: 815 | C59: =B59-(B59*0.25) -> 611.25
A60: FCS-9525 | B60: 600 | C60: =B60-(B60*0.25) -> 450
A61: FCS-9406 | B61: 600 | C61: =B61-(B61*0.25) -> 450
A62: FCS-9951 | B62: 600 | C62: =B62-(B62*0.25) -> 450
A63: FCS-9929 | B63: 750 | C63: =B63-(B63*0.25) -> 562.5
A64: FCS-9950 | B64: 815 | C64: =B64-(B64*0.25) -> 611.25
A65: FCS-9555 | B65: 560 | C65: =B65-(B65*0.25) -> 420
A66: FCS-9868 | B66: 850 | C66: =B66-(B66*0.25) -> 637.5
A67: FCS-9949 | B67: 1050 | C67: =B67-(B67*0.25) -> 787.5
A68: FCS-9526 | B68: 815 | C68: =B68-(B68*0.25) -> 611.25
A69: FCS-9925 | B69: 1075 | C69: =B69-(B69*0.25) -> 806.25
... A94: FCS 9638 | B94: 900 | C94: =B94-(B94*0.25) -> 675
A96: OIL FILTER
A97: UN C-170 | B97: 205 | C97: =B97-(B97*0.25) -> 153.75
A98: UN C-631 | B98: 215 | C98: =B98-(B98*0.25) -> 161.25
A99: UN C-171 | B99: 260 | C99: =B99-(B99*0.25) -> 195
...
